<?xml version="1.0" ?>
<!-- =================================================================================== -->
<!-- |    This document was autogenerated by xacro from Robot_ackerman.xacro           | -->
<!-- |    EDITING THIS FILE BY HAND IS NOT RECOMMENDED                                 | -->
<!-- =================================================================================== -->
<robot name="Robot_ackerman">
  <link name="base_link">
    <visual>
      <geometry>
        <box size="0.5 0.3 0.08"/>
      </geometry>
      <material name="red"/>
    </visual>
    <collision>
      <geometry>
        <box size="0.5 0.3 0.08"/>
      </geometry>
    </collision>
    <inertial>
      <mass value="5.0"/>
      <inertia ixx="0.025" ixy="0.0" ixz="0.0" iyy="0.025" iyz="0.0" izz="0.1"/>
    </inertial>
  </link>
  <link name="right_rear_wheel">
    <visual>
      <geometry>
        <cylinder length="0.1" radius="0.08"/>
      </geometry>
      <material name="black"/>
    </visual>
    <collision>
      <geometry>
        <cylinder length="0.1" radius="0.08"/>
      </geometry>
    </collision>
    <inertial>
      <mass value="0.5"/>
      <inertia ixx="0.12166666666666666" ixy="0.0" ixz="0.0" iyy="0.12166666666666666" iyz="0.0" izz="0.016"/>
    </inertial>
  </link>
  <link name="left_rear_wheel">
    <visual>
      <geometry>
        <cylinder length="0.1" radius="0.08"/>
      </geometry>
      <material name="black"/>
    </visual>
    <collision>
      <geometry>
        <cylinder length="0.1" radius="0.08"/>
      </geometry>
    </collision>
    <inertial>
      <mass value="0.5"/>
      <inertia ixx="0.12166666666666666" ixy="0.0" ixz="0.0" iyy="0.12166666666666666" iyz="0.0" izz="0.016"/>
    </inertial>
  </link>
  <link name="right_front_wheel">
    <visual>
      <geometry>
        <cylinder length="0.1" radius="0.08"/>
      </geometry>
      <material name="black"/>
    </visual>
    <collision>
      <geometry>
        <cylinder length="0.1" radius="0.08"/>
      </geometry>
    </collision>
    <inertial>
      <mass value="0.5"/>
      <inertia ixx="0.02166666666666666" ixy="0.0" ixz="0.0" iyy="0.12166666666666666" iyz="0.0" izz="0.016"/>
    </inertial>
  </link>
  <link name="left_front_wheel">
    <visual>
      <geometry>
        <cylinder length="0.1" radius="0.08"/>
      </geometry>
      <material name="black"/>
    </visual>
    <collision>
      <geometry>
        <cylinder length="0.5" radius="0.08"/>
      </geometry>
    </collision>
    <inertial>
      <mass value="5.0"/>
      <inertia ixx="0.12166666666666666" ixy="0.0" ixz="0.0" iyy="0.12166666666666666" iyz="0.0" izz="0.016"/>
    </inertial>
  </link>
  <link name="right_front_wheel_turn">
    <visual>
      <geometry>
        <cylinder length="0.04" radius="0.05"/>
      </geometry>
      <material name="green"/>
    </visual>
    <collision>
      <geometry>
        <cylinder length="0.04" radius="0.05"/>
      </geometry>
    </collision>
    <inertial>
      <mass value="0.5"/>
      <inertia ixx="0.00677" ixy="0" ixz="0" iyy="0.00677" iyz="0" izz="0.0125"/>
    </inertial>
  </link>
  <link name="left_front_wheel_turn">
    <visual>
      <geometry>
        <cylinder length="0.04" radius="0.05"/>
      </geometry>
      <material name="green"/>
    </visual>
    <collision>
      <geometry>
        <cylinder length="0.04" radius="0.05"/>
      </geometry>
    </collision>
    <inertial>
      <mass value="0.5"/>
      <inertia ixx="0.00677" ixy="0" ixz="0" iyy="0.00677" iyz="0" izz="0.0125"/>
    </inertial>
  </link>
  <joint name="right_rear_wheel_joint" type="continuous">
    <parent link="base_link"/>
    <child link="right_rear_wheel"/>
    <origin rpy="1.57 0.0 0.0" xyz="0.25 0.20 0"/>
    <axis xyz="0.0 0.0 1.0"/>
  </joint>
  <joint name="left_rear_wheel_joint" type="continuous">
    <parent link="base_link"/>
    <child link="left_rear_wheel"/>
    <origin rpy="1.57 0.0 0.0" xyz="0.25 -0.20 0.0"/>
    <axis xyz="0.0 0.0 1.0"/>
  </joint>
  <joint name="right_front_wheel_joint" type="continuous">
    <parent link="right_front_wheel_turn"/>
    <child link="right_front_wheel"/>
    <origin rpy="0.0 0.0 0.0" xyz="0 0 0"/>
    <axis xyz="0.0 0.0 1"/>
  </joint>
  <joint name="left_front_wheel_joint" type="continuous">
    <parent link="left_front_wheel_turn"/>
    <child link="left_front_wheel"/>
    <origin rpy="0.0 0.0 0.0" xyz="0 0 0"/>
    <axis xyz="0.0 0.0 1"/>
  </joint>
  <joint name="right_steering_joint" type="revolute">
    <parent link="base_link"/>
    <child link="right_front_wheel_turn"/>
    <origin rpy="1.57 0.0 0.0" xyz="-0.25 0.20 0.0"/>
    <axis xyz="0.0 1.0 0.0"/>
    <limit effort="100" lower="-0.6" upper="0.6" velocity="0.5"/>
  </joint>
  <joint name="left_steering_joint" type="revolute">
    <parent link="base_link"/>
    <child link="left_front_wheel_turn"/>
    <origin rpy="1.57 0.0 0.0" xyz="-0.25 -0.20 0.0"/>
    <axis xyz="0.0 1.0 0.0"/>
    <limit effort="100" lower="-0.6" upper="0.6" velocity="0.5"/>
  </joint>

    <gazebo>
        <plugin name="gazebo_ros_ackermann_drive" filename="libgazebo_ros_ackermann_drive.so">

            <update_rate>400.0</update_rate>

            <!-- wheels -->
            <left_front_joint>left_steering_joint</left_front_joint>
            <right_front_joint>right_steering_joint</right_front_joint>
            <left_rear_joint>left_rear_wheel_joint</left_rear_joint>
            <right_rear_joint>right_rear_wheel_joint</right_rear_joint>
            <left_front_wheel>left_front_wheel_joint</left_front_wheel>
            <right_front_wheel>right_front_wheel_joint</right_front_wheel>

            <!-- Max absolute steer angle for tyre in radians-->
            <!-- Any cmd_vel angular z greater than this would be capped -->
            <max_steer>0.6458</max_steer>

            <!-- Max absolute steering angle of steering wheel -->
            <max_steering_angle>7.85</max_steering_angle>

            <!-- Max absolute linear speed in m/s -->
            <max_speed>20</max_speed>

            <!-- PID tuning -->
            <left_steering_pid_gain>100 0.01 0.1</left_steering_pid_gain>
            <right_steering_pid_gain>100 0.01 0.1</right_steering_pid_gain>
            <linear_velocity_pid_gain>50 0.01 0.1</linear_velocity_pid_gain>
            
            <left_steering_i_range>-0.05 0.05</left_steering_i_range>
            <right_steering_i_range>-0.05 0.05</right_steering_i_range>
            <linear_velocity_i_range>-0.05 0.05</linear_velocity_i_range>

            <!-- output -->
            <publish_odom>true</publish_odom>
            <publish_odom_tf>true</publish_odom_tf>
            <publish_wheel_tf>true</publish_wheel_tf>
            <publish_distance>true</publish_distance>

            <odometry_frame>odom_demo</odometry_frame>
            <robot_base_frame>base_link</robot_base_frame>
        </plugin>
    </gazebo>
</robot>