<?xml version="1.0"?>
<robot name="Robot_ackerman" xmlns:xacro="http://www.ros.org/wiki/xacro">

  <xacro:property name="wheel_radius" value="0.08" />
  <xacro:property name="wheel_length" value="0.1" />
  <xacro:property name="wheel_mass" value="0.9" />
  <xacro:property name="wheel_color" value="0.0 0.0 0.0 1.0" /> 
  <xacro:property name="base_size" value="0.5 0.3 0.08" />
  <xacro:property name="base_mass" value="0.9"/>
  <xacro:property name="base_color" value="1 0 0 0.8"/>

  <xacro:macro name="cylinder_link" params="link_name color">
    <link name="${link_name}">
      <visual>
        <geometry>
          <cylinder radius="${wheel_radius}" length="${wheel_length}"/>
        </geometry>
        <material name="material_${link_name}">
          <color rgba="${color}"/>
        </material>
      </visual>
      <collision>
        <geometry>
          <cylinder radius="${wheel_radius}" length="${wheel_length}"/>
        </geometry>
      </collision>
      <inertial>
        <origin xyz="0 0 0" rpy="0 0 0"/>
        <mass value="${wheel_mass}"/>
        <inertia ixx="0.25" ixy="0" ixz="0" iyy="0.25" iyz="0" izz="0.1"/>
      </inertial>
    </link>
  </xacro:macro>

  <xacro:macro name="wheel_joint" params="joint_name parent_link child_link origin axis">
    <joint name="${joint_name}" type="continuous">
      <parent link="${parent_link}"/>
      <child link="${child_link}"/>
      <origin xyz="${origin}" rpy="1.57 0 0"/>
      <axis xyz="${axis}"/>
    </joint>
  </xacro:macro>

  <link name="base_link">
    <visual>
      <geometry>
        <box size="${base_size}"/>
      </geometry>
      <material name="red">
        <color rgba="${base_color}"/>
      </material>
    </visual>
    </link>
  <xacro:cylinder_link link_name="right_rear_wheel" color="${wheel_color}"/>
  <xacro:cylinder_link link_name="left_rear_wheel" color="${wheel_color}"/> 
  </robot>
