<?xml version="1.0"?>
<robot name="Robot_ackerman" xmlns:xacro="http://www.ros.org/wiki/xacro">

  <xacro:property name="wheel_radius" value="0.08"/>
  <xacro:property name="wheel_length" value="0.1"/>
  <xacro:property name="base_size" value="0.5 0.3 0.08"/>
  <xacro:property name="pi" value="3.14159265359"/>
  <xacro:property name="wheel_mass" value="5.0"/>
  <xacro:property name="turn_radius" value="0.05"/>

  <xacro:macro name="cylinder_inertia" params="m r h">
    <inertia ixx="${m*(3*r*r+h*h)/12}" ixy="0.0" ixz="0.0" 
             iyy="${m*(3*r*r+h*h)/12}" iyz="0.0" izz="${m*r*r/2}"/>
  </xacro:macro>

  <xacro:macro name="wheel" params="prefix suffix">
    <link name="${prefix}_${suffix}_wheel">
      <visual>
        <geometry>
          <cylinder radius="${wheel_radius}" length="${wheel_length}"/>
        </geometry>
        <material name="black"/>
      </visual>
      <collision>
        <geometry>
          <cylinder radius="${wheel_radius}" length="${wheel_length}"/>
        </geometry>
      </collision>
      <inertial>
        <mass value="${wheel_mass}"/>
        <xacro:cylinder_inertia m="${wheel_mass}" r="${wheel_radius}" h="${wheel_length}"/>
      </inertial>
    </link>
  </xacro:macro>

  <xacro:macro name="wheel_turn" params="prefix">
    <link name="${prefix}_front_wheel_turn">
      <visual>
        <geometry>
          <cylinder length="0.04" radius="${turn_radius}"/>
        </geometry>
        <material name="green"/>
      </visual>
      <collision>
        <geometry>
          <cylinder length="0.04" radius="${turn_radius}"/>
        </geometry>
      </collision>
      <inertial>
        <mass value="1.0"/>  
        <inertia ixx="0.000677" ixy="0" ixz="0" iyy="0.000677" iyz="0" izz="0.00125"/>
      </inertial>
    </link>
  </xacro:macro>

  <link name="base_link">
    <visual>
      <geometry>
        <box size="${base_size}"/>
      </geometry>
      <material name="red"/>
    </visual>
    <collision>
      <geometry>
        <box size="${base_size}"/>
      </geometry>
    </collision>
    <inertial>
      <mass value="10.0"/>
      <inertia ixx="0.025" ixy="0.0" ixz="0.0" iyy="0.025" iyz="0.0" izz="0.01"/> 
    </inertial>
  </link>

  <xacro:wheel prefix="right" suffix="rear"/>
  <xacro:wheel prefix="left" suffix="rear"/>
  <xacro:wheel prefix="right" suffix="front"/>
  <xacro:wheel prefix="left" suffix="front"/>
  <xacro:wheel_turn prefix="right"/>
  <xacro:wheel_turn prefix="left"/>
  <joint name="right_rear_wheel_joint" type="continuous">
    <parent link="base_link"/>
    <child link="right_rear_wheel"/>
    <origin xyz="0.25 0.20 0" rpy="1.57 0.0 0.0"/>
    <axis xyz="0.0 0.0 1.0"/>
  </joint>

  <joint name="left_rear_wheel_joint" type="continuous">
    <parent link="base_link"/>
    <child link="left_rear_wheel"/>
    <origin xyz="0.25 -0.20 0.0" rpy="1.57 0.0 0.0"/>
    <axis xyz="0.0 0.0 1.0"/>
  </joint>

  <joint name="right_front_wheel_joint" type="continuous">
    <parent link="right_front_wheel_turn"/>
    <child link="right_front_wheel"/>
    <origin xyz="0 0 0" rpy="0.0 0.0 0.0"/>
    <axis xyz="0.0 0.0 1"/>
  </joint>

  <joint name="left_front_wheel_joint" type="continuous">
    <parent link="left_front_wheel_turn"/>
    <child link="left_front_wheel"/>
    <origin xyz="0 0 0" rpy="0.0 0.0 0.0"/>
    <axis xyz="0.0 0.0 1"/>
  </joint>

  <joint name="right_steering_joint" type="revolute">
    <parent link="base_link"/>
    <child link="right_front_wheel_turn"/>
    <origin xyz="-0.25 0.20 0.0" rpy="1.57 0.0 0.0"/>
    <axis xyz="0.0 1.0 0.0"/>
    <limit lower="-0.6" upper="0.6" effort="100" velocity="0.5"/>
  </joint>

  <joint name="left_steering_joint" type="revolute">
    <parent link="base_link"/>
    <child link="left_front_wheel_turn"/>
    <origin xyz="-0.25 -0.20 0.0" rpy="1.57 0.0 0.0"/>
    <axis xyz="0.0 1.0 0.0"/>
    <limit lower="-0.6" upper="0.6" effort="100" velocity="0.5"/>
  </joint>
