<?xml version="1.0" ?>
<!-- =================================================================================== -->
<!-- |    This document was autogenerated by xacro from Robot_ackerman.xacro           | -->
<!-- |    EDITING THIS FILE BY HAND IS NOT RECOMMENDED                                 | -->
<!-- =================================================================================== -->
<robot name="Robot_ackerman">
  <link name="base_link">
    <visual>
      <geometry>
        <box size="0.5 0.3 0.08"/>
      </geometry>
      <material name="red"/>
    </visual>
    <collision>
      <geometry>
        <box size="0.5 0.3 0.08"/>
      </geometry>
    </collision>
    <inertial>
      <mass value="10.0"/>
      <inertia ixx="0.25" ixy="0.0" ixz="0.0" iyy="0.25" iyz="0.0" izz="0.1"/>
    </inertial>
  </link>
  <link name="right_rear_wheel">
    <visual>
      <geometry>
        <cylinder length="0.1" radius="0.08"/>
      </geometry>
      <material name="black"/>
    </visual>
    <collision>
      <geometry>
        <cylinder length="0.1" radius="0.08"/>
      </geometry>
    </collision>
    <inertial>
      <mass value="5.0"/>
      <inertia ixx="0.12166666666666666" ixy="0.0" ixz="0.0" iyy="0.12166666666666666" iyz="0.0" izz="0.016"/>
    </inertial>
  </link>
  <link name="left_rear_wheel">
    <visual>
      <geometry>
        <cylinder length="0.1" radius="0.08"/>
      </geometry>
      <material name="black"/>
    </visual>
    <collision>
      <geometry>
        <cylinder length="0.1" radius="0.08"/>
      </geometry>
    </collision>
    <inertial>
      <mass value="5.0"/>
      <inertia ixx="0.12166666666666666" ixy="0.0" ixz="0.0" iyy="0.12166666666666666" iyz="0.0" izz="0.016"/>
    </inertial>
  </link>
  <link name="right_front_wheel">
    <visual>
      <geometry>
        <cylinder length="0.1" radius="0.08"/>
      </geometry>
      <material name="black"/>
    </visual>
    <collision>
      <geometry>
        <cylinder length="0.1" radius="0.08"/>
      </geometry>
    </collision>
    <inertial>
      <mass value="5.0"/>
      <inertia ixx="0.12166666666666666" ixy="0.0" ixz="0.0" iyy="0.12166666666666666" iyz="0.0" izz="0.016"/>
    </inertial>
  </link>
  <link name="left_front_wheel">
    <visual>
      <geometry>
        <cylinder length="0.1" radius="0.08"/>
      </geometry>
      <material name="black"/>
    </visual>
    <collision>
      <geometry>
        <cylinder length="0.1" radius="0.08"/>
      </geometry>
    </collision>
    <inertial>
      <mass value="5.0"/>
      <inertia ixx="0.12166666666666666" ixy="0.0" ixz="0.0" iyy="0.12166666666666666" iyz="0.0" izz="0.016"/>
    </inertial>
  </link>
  <link name="right_front_wheel_turn">
    <visual>
      <geometry>
        <cylinder length="0.04" radius="0.05"/>
      </geometry>
      <material name="green"/>
    </visual>
    <collision>
      <geometry>
        <cylinder length="0.04" radius="0.05"/>
      </geometry>
    </collision>
    <inertial>
      <mass value="1.0"/>
      <inertia ixx="0.000677" ixy="0" ixz="0" iyy="0.000677" iyz="0" izz="0.00125"/>
    </inertial>
  </link>
  <link name="left_front_wheel_turn">
    <visual>
      <geometry>
        <cylinder length="0.04" radius="0.05"/>
      </geometry>
      <material name="green"/>
    </visual>
    <collision>
      <geometry>
        <cylinder length="0.04" radius="0.05"/>
      </geometry>
    </collision>
    <inertial>
      <mass value="1.0"/>
      <inertia ixx="0.000677" ixy="0" ixz="0" iyy="0.000677" iyz="0" izz="0.00125"/>
    </inertial>
  </link>
  <joint name="right_rear_wheel_joint" type="continuous">
    <parent link="base_link"/>
    <child link="right_rear_wheel"/>
    <origin rpy="1.57 0.0 0.0" xyz="0.25 0.20 0"/>
    <axis xyz="0.0 0.0 1.0"/>
  </joint>
  <joint name="left_rear_wheel_joint" type="continuous">
    <parent link="base_link"/>
    <child link="left_rear_wheel"/>
    <origin rpy="1.57 0.0 0.0" xyz="0.25 -0.20 0.0"/>
    <axis xyz="0.0 0.0 1.0"/>
  </joint>
  <joint name="right_front_wheel_joint" type="continuous">
    <parent link="right_front_wheel_turn"/>
    <child link="right_front_wheel"/>
    <origin rpy="0.0 0.0 0.0" xyz="0 0 0"/>
    <axis xyz="0.0 0.0 1"/>
  </joint>
  <joint name="left_front_wheel_joint" type="continuous">
    <parent link="left_front_wheel_turn"/>
    <child link="left_front_wheel"/>
    <origin rpy="0.0 0.0 0.0" xyz="0 0 0"/>
    <axis xyz="0.0 0.0 1"/>
  </joint>
  <joint name="right_steering_joint" type="revolute">
    <parent link="base_link"/>
    <child link="right_front_wheel_turn"/>
    <origin rpy="1.57 0.0 0.0" xyz="-0.25 0.20 0.0"/>
    <axis xyz="0.0 1.0 0.0"/>
    <limit effort="100" lower="-0.6" upper="0.6" velocity="0.5"/>
  </joint>
  <joint name="left_steering_joint" type="revolute">
    <parent link="base_link"/>
    <child link="left_front_wheel_turn"/>
    <origin rpy="1.57 0.0 0.0" xyz="-0.25 -0.20 0.0"/>
    <axis xyz="0.0 1.0 0.0"/>
    <limit effort="100" lower="-0.6" upper="0.6" velocity="0.5"/>
  </joint>
</robot>
